Workbook

Sheet Membership Level
A2: Levels | B2: Duration (Months) | C2: DAYS
A3: Cricket Month | B3: 1 | C3: =30*B3 -> 30
A4: Cricket Qty | B4: 3 | C4: =30*B4 -> 90
A5: Cricket HY | B5: 6 | C5: =30*B5 -> 180
A6: Cricket Y | B6: 12 | C6: =30*B6 -> 360
A7: Tennis Moth | B7: 1 | C7: =30*B7 -> 30
A8: Tennis Qty | B8: 3 | C8: =30*B8 -> 90
A9: Tennis HY | B9: 6 | C9: =30*B9 -> 180
A10: Tennis Y | B10: 12 | C10: =30*B10 -> 360
A11: Swimming 2 Moth | B11: 2 | C11: =30*B11 -> 60
A12: Swimming Moth | B12: 1 | C12: =30*B12 -> 30
A13: Swimming Qty | B13: 3 | C13: =30*B13 -> 90
A14: Swimming HY | B14: 6 | C14: =30*B14 -> 180
... A19: ZUMBA QTY | B19: 3 | C19: =30*B19 -> 90
A20: SKATING MONTH | B20: 1 | C20: 30
A21: SKATING QTY | B21: 3 | C21: 90
F39: ='Membership Level'!A1 -> 0

Sheet SWIMMING 2026
D2: Club Membership Database | E2: -2026
C5: =3300*30/100 -> 990
A7: Contact Information | F7: Membership | M7: Notice term
A8: REG NO | B8: REG, DATE | C8: Last Name | D8: First Name | E8: MOBILE NO. | F8: Level | G8: DAYS | H8: Membership Fees | I8: Fees Paid | J8: Fees Due | K8: Start | L8: Expiration | M8: Days
A9: CAP/SW/01 | B9: 46057 | C9: CHOUIDHARY | D9: SANCHITA | F9: ='Membership Level'!A12 -> Swimming Moth | H9: 4400 | I9: 4400 | J9: =H9-I9 -> 0 | K9: 46057 | L9: =DATE(YEAR(K9),MONTH(K9)+VLOOKUP($F9,'Membership Level'!$A$3:$B$15,2,FALSE),DAY(K9)) -> 46085 | M9: 3
A10: CAP/SW/02 | B10: 46067 | C10: K | D10: PRANJAL | E10: 9113785019 | F10: ='Membership Level'!A14 -> Swimming HY | G10: 6 MONTHS | H10: 18000 | I10: 18000 | J10: =H10-I10 -> 0 | K10: 46070 | L10: =DATE(YEAR(K10),MONTH(K10)+VLOOKUP($F10,'Membership Level'!$A$3:$B$15,2,FALSE),DAY(K10)) -> 46251 | M10: 3
A11: CAP/SW/03 | B11: 46069 | C11: KUMARI | D11: NEHA | E11: 9711983243 | F11: ='Membership Level'!A12 -> Swimming Moth | G11: 2 DAYS | H11: 2500 | I11: 2500 | J11: =H11-I11 -> 0 | K11: 46070 | L11: =DATE(YEAR(K11),MONTH(K11)+VLOOKUP($F11,'Membership Level'!$A$3:$B$15,2,FALSE),DAY(K11)) -> 46098 | M11: 3
A12: CAP/SW/04 | B12: 46069 | C12: SINGH | D12: ASMITA | E12: 8552081564 | F12: ='Membership Level'!A12 -> Swimming Moth | G12: 2 DAYS | H12: 2500 | I12: 2500 | J12: =H12-I12 -> 0 | K12: 46070 | L12: =DATE(YEAR(K12),MONTH(K12)+VLOOKUP($F12,'Membership Level'!$A$3:$B$15,2,FALSE),DAY(K12)) -> 46098 | M12: 3
A13: CAP/SW/05 | B13: 46069 | C13: SINGH | D13: SHIVAM | E13: 8757640445 | F13: ='Membership Level'!A12 -> Swimming Moth | H13: 4400 | I13: 4400 | J13: =H13-I13 -> 0 | K13: 46070 | L13: =DATE(YEAR(K13),MONTH(K13)+VLOOKUP($F13,'Membership Level'!$A$3:$B$15,2,FALSE),DAY(K13)) -> 46098 | M13: 3
A14: CAP/SW/06 | B14: 46069 | C14: DR PALLAVI | E14: 7903400253 | F14: ='Membership Level'!A12 -> Swimming Moth | H14: 4400 | I14: 4400 | J14: =H14-I14 -> 0 | K14: 46070 | L14: =DATE(YEAR(K14),MONTH(K14)+VLOOKUP($F14,'Membership Level'!$A$3:$B$15,2,FALSE),DAY(K14)) -> 46098 | M14: 3
A15: CAP/SW/07 | B15: 46070 | C15: RAJENDRAN | D15: KARTHIK | E15: 9999014349 | F15: ='Membership Level'!A12 -> Swimming Moth | G15: MONTHLY | H15: 4400 | I15: 4400 | J15: =H15-I15 -> 0 | K15: 46143 | L15: =DATE(YEAR(K15),MONTH(K15)+VLOOKUP($F15,'Membership Level'!$A$3:$B$15,2,FALSE),DAY(K15)) -> 46174 | M15: 3
A16: CAP/SW/08 | B16: 46070 | C16: JHA | D16: KISHLAY | E16: 9999467539 | F16: ='Membership Level'!A13 -> Swimming Qty | G16: 3 MONTHS | H16: 11500 | I16: 11500 | J16: =H16-I16 -> 0 | K16: 46070 | L16: =DATE(YEAR(K16),MONTH(K16)+VLOOKUP($F16,'Membership Level'!$A$3:$B$15,2,FALSE),DAY(K16)) -> 46159
A17: CAP/SW/09 | B17: 46070 | C17: SINHA | D17: DR.SOUMYA | E17: 9304880904 | F17: ='Membership Level'!A12 -> Swimming Moth | H17: 4000 | I17: 4000 | J17: =H17-I17 -> 0 | K17: 46070 | L17: =DATE(YEAR(K17),MONTH(K17)+VLOOKUP($F17,'Membership Level'!$A$3:$B$15,2,FALSE),DAY(K17)) -> 46098 | M17: 3
A18: CAP/SW/10 | B18: 46071 | C18: SINGH | D18: DEEPAK KUMAR | E18: 7676011492 | F18: ='Membership Level'!A12 -> Swimming Moth | H18: 4000 | I18: 4000 | J18: =H18-I18 -> 0 | K18: 46071 | L18: =DATE(YEAR(K18),MONTH(K18)+VLOOKUP($F18,'Membership Level'!$A$3:$B$15,2,FALSE),DAY(K18)) -> 46099 | M18: 3
A19: CAP/SW/11 | B19: 46071 | C19: KUMAR | D19: PRATIK | E19: 8578000035 | F19: ='Membership Level'!A12 -> Swimming Moth | H19: 4000 | I19: 4000 | J19: =H19-I19 -> 0 | K19: 46130 | L19: 46160 | M19: 3
A20: CAP/SW/12 | B20: 46071 | C20: PODDAR | D20: PREETI | E20: 6203439924 | F20: ='Membership Level'!A12 -> Swimming Moth | H20: 4000 | I20: 4000 | J20: =H20-I20 -> 0 | K20: 46071 | L20: 46099
A21: CAP/SW/13 | B21: 46072 | C21: KUMAR | D21: ASHISH | E21: 8169375056 | F21: ='Membership Level'!A12 -> Swimming Moth | G21: MONTHLY | H21: 4400 | I21: 4400 | J21: =H21-I21 -> 0 | K21: 46071 | L21: 46100 | M21: 3
A22: CAP/SW/14 | B22: 46072 | D22: CHANDRAWEEN | E22: 9674155448 | F22: ='Membership Level'!A12 -> Swimming Moth | H22: 4400 | I22: 4400 | J22: =H22-I22 -> 0 | K22: 46072 | L22: =DATE(YEAR(K22),MONTH(K22)+VLOOKUP($F22,'Membership Level'!$A$3:$B$15,2,FALSE),DAY(K22)) -> 46100 | M22: 3
A23: CAP/SW/15 | B23: 46072 | C23: SINHA | D23: DURGESH | E23: 8886990845 | F23: ='Membership Level'!A14 -> Swimming HY | G23: 6 MONTHS | H23: 16000 | I23: 16000 | J23: =H23-I23 -> 0 | K23: 46072 | L23: 46253 | M23: 3
A24: CAP/SW/16 | B24: 46071 | C24: KUMAR | D24: RUPESH | E24: 7676011492 | F24: ='Membership Level'!A12 -> Swimming Moth | G24: 3 DAYS | H24: 3000 | I24: 3000 | J24: =H24-I24 -> 0 | K24: 46160 | L24: =DATE(YEAR(K24),MONTH(K24)+VLOOKUP($F24,'Membership Level'!$A$3:$B$15,2,FALSE),DAY(K24)) -> 46191 | M24: 3
A25: CAP/SW/17 | B25: 46073 | C25: BHARTI | D25: NESH RAJ | E25: 9548107173 | F25: ='Membership Level'!A12 -> Swimming Moth | G25: 2 DAYS | H25: 2500 | I25: 2500 | J25: =H25-I25 -> 0 | K25: 46073 | L25: =DATE(YEAR(K25),MONTH(K25)+VLOOKUP($F25,'Membership Level'!$A$3:$B$15,2,FALSE),DAY(K25)) -> 46101
A26: CAP/SW/18 | B26: 46074 | C26: VARDHAN | D26: SIDHARTH | E26: 9304716545 | F26: ='Membership Level'!A12 -> Swimming Moth | G26: 3 DAYS | H26: 3300 | I26: 3300 | K26: 46102 | L26: =DATE(YEAR(K26),MONTH(K26)+VLOOKUP($F26,'Membership Level'!$A$3:$B$15,2,FALSE),DAY(K26)) -> 46133
A27: CAP/SW/19 | B27: 46074 | C27: RAY | D27: JAYJIT | E27: 9471006930 | F27: ='Membership Level'!A12 -> Swimming Moth | G27: 3 DAYS | H27: 3300 | I27: 3300 | J27: =H27-I27 -> 0 | K27: 46102 | L27: =DATE(YEAR(K27),MONTH(K27)+VLOOKUP($F27,'Membership Level'!$A$3:$B$15,2,FALSE),DAY(K27)) -> 46133 | M27: 3
A28: CAP/SW/20 | B28: 46074 | D28: DR. NISHANT | E28: 9073139001 | F28: ='Membership Level'!A12 -> Swimming Moth | G28: 3 DAYS | H28: 3000 | I28: 3000 | J28: =H28-I28 -> 0 | K28: 46074 | L28: =DATE(YEAR(K28),MONTH(K28)+VLOOKUP($F28,'Membership Level'!$A$3:$B$15,2,FALSE),DAY(K28)) -> 46102 | M28: 3
A29: CAP/SW/21 | B29: 46074 | C29: I.C YADAV | D29: ISHWAR CHANDRA (I.C . YADAV ) | E29: 9279086474 | F29: ='Membership Level'!A13 -> Swimming Qty | G29: 9 MONTHS | H29: 24700 | I29: 24700 | J29: =H29-I29 -> 0 | K29: 46074 | L29: =DATE(YEAR(K29),MONTH(K29)+VLOOKUP($F29,'Membership Level'!$A$3:$B$15,2,FALSE),DAY(K29)) -> 46163 | M29: 3
A30: CAP/SW/22 | B30: 46074 | C30: PRAYADASHI | D30: SRITABH | E30: 7306597482 | F30: ='Membership Level'!A12 -> Swimming Moth | G30: 2 DAYS | H30: 2500 | I30: 2500 | J30: =H30-I30 -> 0 | K30: 46133 | L30: =DATE(YEAR(K30),MONTH(K30)+VLOOKUP($F30,'Membership Level'!$A$3:$B$15,2,FALSE),DAY(K30)) -> 46163 | M30: 3
A31: CAP/SW/23 | B31: 46074 | C31: GHOSH | D31: SAYANI DAS | E31: 8910553619 | F31: SWIMMING QTY | G31: 3 MONTHS(3DAYS) | H31: 8500 | I31: 8500 | J31: =H31-I31 -> 0 | K31: 46074 | L31: 46163 | M31: 3
A32: CAP/SW/24 | B32: 46075 | C32: KUMARI | D32: VIBHA | E32: 7549725852 | F32: ='Membership Level'!A12 -> Swimming Moth | G32: MONTHLY | H32: 4400 | I32: 4400 | J32: =H32-I32 -> 0 | K32: 46075 | L32: =DATE(YEAR(K32),MONTH(K32)+VLOOKUP($F32,'Membership Level'!$A$3:$B$15,2,FALSE),DAY(K32)) -> 46103 | M32: 3
A33: CAP/SW/25 | B33: 46075 | C33: RAJ | D33: AMAN | E33: 9386886568 | F33: ='Membership Level'!A12 -> Swimming Moth | G33: MONTHLY | H33: 4400 | I33: 4400 | J33: =H33-I33 -> 0 | K33: 46075 | L33: =DATE(YEAR(K33),MONTH(K33)+VLOOKUP($F33,'Membership Level'!$A$3:$B$15,2,FALSE),DAY(K33)) -> 46103 | M33: 3
A34: CAP/SW/26 | B34: 46075 | D34: ARNAV | E34: 8146089048 | F34: ='Membership Level'!A12 -> Swimming Moth | G34: MONTHLY (2 DAYS ) | H34: 2000 | I34: 2000 | J34: =H34-I34 -> 0 | K34: 46075 | L34: =DATE(YEAR(K34),MONTH(K34)+VLOOKUP($F34,'Membership Level'!$A$3:$B$15,2,FALSE),DAY(K34)) -> 46103 | M34: 3
A35: CAP/SW/27 | B35: 46075 | C35: PANDEY | D35: PANKAJ | E35: 8146089048 | F35: ='Membership Level'!A12 -> Swimming Moth | G35: MONTHLY (2 DAYS ) | H35: 2000 | I35: 2000 | J35: =H35-I35 -> 0 | K35: 46075 | L35: =DATE(YEAR(K35),MONTH(K35)+VLOOKUP($F35,'Membership Level'!$A$3:$B$15,2,FALSE),DAY(K35)) -> 46103 | M35: 3
A36: CAP/SW/28 | B36: 46075 | C36: DEY | D36: DEVANSHI | E36: 9893183545 | F36: ='Membership Level'!A12 -> Swimming Moth | G36: MONTHLY | H36: 3500 | I36: 3500 | J36: =H36-I36 -> 0 | K36: 46136 | L36: =DATE(YEAR(K36),MONTH(K36)+VLOOKUP($F36,'Membership Level'!$A$3:$B$15,2,FALSE),DAY(K36)) -> 46166 | M36: 3
A37: CAP/SW/29 | B37: 46075 | C37: SINGH | D37: EKTA | E37: 8340571295 | F37: ='Membership Level'!A12 -> Swimming Moth | G37: MONTHLY | H37: 4000 | I37: 4000 | J37: =H37-I37 -> 0 | K37: 46075 | L37: =DATE(YEAR(K37),MONTH(K37)+VLOOKUP($F37,'Membership Level'!$A$3:$B$15,2,FALSE),DAY(K37)) -> 46103
A38: CAP/SW/30 | B38: 46077 | C38: ANAND | D38: SHANKAR | E38: 8969827290 | F38: ='Membership Level'!A12 -> Swimming Moth | G38: 3 DAYS | H38: 3000 | I38: 3000 | J38: =H38-I38 -> 0 | K38: 46077 | L38: =DATE(YEAR(K38),MONTH(K38)+VLOOKUP($F38,'Membership Level'!$A$3:$B$15,2,FALSE),DAY(K38)) -> 46105 | M38: 3
A39: CAP/SW/31 | B39: 46077 | C39: BAYAHUT | D39: ARNIKA | E39: 8757993589 | F39: ='Membership Level'!A13 -> Swimming Qty | G39: 3 MONTHS (3 DAYS ) | H39: 7500 | I39: 7500 | J39: =H39-I39 -> 0 | K39: 46077 | L39: 46166 | M39: 3
A40: CAP/SW/32 | B40: 46077 | C40: SHANKAR | D40: RAVI | E40: 9661117444 | F40: ='Membership Level'!A12 -> Swimming Moth | G40: MONTHLY | H40: 4000 | I40: 4000 | J40: =H40-I40 -> 0 | K40: 46077 | L40: =DATE(YEAR(K40),MONTH(K40)+VLOOKUP($F40,'Membership Level'!$A$3:$B$15,2,FALSE),DAY(K40)) -> 46105 | M40: 3
A41: CAP/SW/33 | B41: 46077 | D41: DEEPANSHU | E41: 8873630016 | F41: ='Membership Level'!A12 -> Swimming Moth | G41: MONTHLY | H41: 4400 | I41: 4400 | J41: =H41-I41 -> 0 | K41: 46150 | L41: =DATE(YEAR(K41),MONTH(K41)+VLOOKUP($F41,'Membership Level'!$A$3:$B$15,2,FALSE),DAY(K41)) -> 46181 | M41: 3
A42: CAP/SW/34 | B42: 46077 | D42: SUBHDA | E42: 9262325017 | F42: ='Membership Level'!A12 -> Swimming Moth | G42: MONTHLY (3 DAY) | H42: 2800 | I42: 2800 | J42: =H42-I42 -> 0 | K42: 46136 | L42: =DATE(YEAR(K42),MONTH(K42)+VLOOKUP($F42,'Membership Level'!$A$3:$B$15,2,FALSE),DAY(K42)) -> 46166 | M42: 3
A43: CAP/SW/35 | B43: 46078 | C43: VERMA | D43: H.P | E43: 9905415111 | F43: ='Membership Level'!A14 -> Swimming HY | G43: 6 MONTHS | H43: 18000 | I43: 18000 | J43: =H43-I43 -> 0 | K43: 46077 | L43: =DATE(YEAR(K43),MONTH(K43)+VLOOKUP($F43,'Membership Level'!$A$3:$B$15,2,FALSE),DAY(K43)) -> 46258 | M43: 3
A44: CAP/SW/36 | B44: 46078 | C44: SHARMA | D44: SHREYA | E44: 9205642415 | F44: ='Membership Level'!A12 -> Swimming Moth | G44: MONTHLY | H44: 3800 | I44: 3800 | J44: =H44-I44 -> 0 | K44: 46108 | L44: =DATE(YEAR(K44),MONTH(K44)+VLOOKUP($F44,'Membership Level'!$A$3:$B$15,2,FALSE),DAY(K44)) -> 46139 | M44: 3
...

Sheet Sheet4
A1: 3800 | B1: 3800
A2: 10600 | B2: 10600
A3: 4400+1000 | B3: 5400
A4: 11500 (3500 DUES ) | B4: 8000
A5: 2500 | B5: 2500
A6: 2500 | B6: 2500
A7: 2500 | B7: 2500
A8: 3500 | B8: 3500
A9: 3500 | B9: 3500
A10: 2800 | B10: 2800
A11: 2800 | B11: 2800
A12: 2800 | B12: 2800
A13: 2500+1000 | B13: 3500
A14: 2200 | B14: 2200
A15: 4400+1000 | B15: 5400
A16: 3300 | B16: 3300
A17: 2800 | B17: 2800
A18: 3800+1000 | B18: 4800
A19: 2800 | B19: 2800
A20: 250 | B20: 250
A21: 2800+1000 | B21: 3800
A22: 400 | B22: 400
A23: 3800+1000 | B23: 4800
A24: 3800 | B24: 3800
A25: 4400+1000 | B25: 5400
A26: 1000 | B26: 1000
A27: 1000 | B27: 1000
A28: 8000 | B28: 8000
A29: 8000 | B29: 8000
A30: 8000 | B30: 8000
A31: 4000 | B31: 4000
A32: 4400+1000 | B32: 5400
A33: 3500 | B33: 3500
A34: 2800 | B34: 2800
A35: 4000+1000 | B35: 5000
A36: 4000+1000 | B36: 5000
A37: 3500+1000 | B37: 4500
A38: 3500+1000 | B38: 4500
A39: 3500 | B39: 3500
A40: 3300 | B40: 3300
...

Sheet Sheet3
A1: 2500 | B1: 2500 | D1: 2500
A2: 2500+1000 | B2: 3500 | E2: 3500
A3: 3500+1000 | B3: 4500 | C3: 4500
A4: 3500+1000 | B4: 4500 | C4: 4500
A5: 350 | B5: 350 | D5: 350
A6: 1000 | B6: 1000 | D6: 1000
A7: 1000 | B7: 1000 | D7: 1000
A8: 1000 | B8: 1000 | D8: 1000
A9: 2500+1000 | B9: 3500 | C9: 3500
A10: 1000 | B10: 1000 | D10: 1350
A11: 1000 | B11: 1000 | D11: 1350
A12: 700 | B12: 700
A13: 350 | B13: 350 | D13: 350
A14: 4400 | B14: 4400 | C14: 4400
A15: 3800+1000 | B15: 4800 | D15: 4800
A16: 3500 | B16: 3500 | D16: 3500
A17: 1800+1000 | B17: 2800 | D17: 2800
A18: 1800+1000 | B18: 2800 | D18: 2800
A19: 2200 | B19: 2200 | D19: 2200
A20: 2500+1000 | B20: 3500 | D20: 3500
A21: 3800 | B21: 3800 | C21: 3800
A22: 5000 | B22: 5000 | E22: 5000 | L22: =40000+1630 -> 41630
A23: 3500 | B23: 3500 | C23: 3500
A24: 3500 | B24: 3500 | C24: 3500
A25: 3500 | B25: 3500 | C25: 3500
A26: 3500 | B26: 0 | E26: 345
A27: 3500 | B27: 3500 | D27: 3500
A28: 3500 | B28: 3500 | E28: 3500 | L28: =104497-41630 -> 62867
A29: 2800 | B29: 2800 | C29: 2800
A30: 3800 | B30: 3800 | D30: 3800 | E30: 0
A31: 5000 | B31: 5000 | D31: 1200 | E31: 5000
A32: 4000+1000 | B32: 5000 | D32: 152 | E32: 5000
B33: =SUM(B1:B32) -> 91800 | C33: =SUM(C1:C32) -> 34000 | D33: =SUM(D1:D32) -> 37152 | E33: =SUM(E1:E32) -> 22345 | G33: =D33+E33 -> 59497 | H33: =C33+D33+E33 -> 93497

Sheet Sheet1
A1: ZUMBA (2026)
A2: START DATE | B2: NAME | C2: MONTH | D2: EXPIRY | E2: CONTACT NO.
A3: 46060 | B3: POOJA YADAV | D3: 46088 | E3: 8210573106
A4: 46065 | B4: ARCHANA KUMARI | C4: 2 MONTHS (500 RETURN) | D4: 46124 | E4: 8544259646
A5: 46063 | B5: AYUSHI | C5: 3 MONTHS | D5: 46152 | E5: 9431430316
A6: 46057 | B6: NAMITA SINGH | D6: 46085 | E6: 9456011198
A7: 46063 | B7: NEELAM | D7: 46091 | E7: 9334384785
A8: 46057 | B8: RESHMA | D8: 46085 | E8: 7549727560
A9: 46064 | B9: SWATI | C9: 3 MONTHS | D9: 46153 | E9: 7782925800
A10: 46074 | B10: SWETA | D10: 46102 | E10: 9939082903

Sheet Sheet2

Sheet CRICKET NIRANJAN
B2: Club Membership Database | G2: CRICKET
N3: =35-22 -> 13
A7: Contact Information | F7: Membership | L7: Notice term
A8: Last Name | B8: First Name | C8: Address | D8: Email | E8: Phone | F8: Level | G8: Membership Fees | H8: Fees Paid | I8: Fees Due | J8: Start | K8: Expiration | L8: Days | M8: Month | N8: Termination Notice | O8: Days To Expiration | P8: Pending Fee Notice | Q8: Notes
N9: =IF($K9<>0,DATE(YEAR($K9),MONTH($K9)-$M9,DAY($K9)-$L9),"") | O9: =IF(DAYS360(NOW(), $K9) >= 0, DAYS360(NOW(), $K9), "")
A10: PATEL | B10: TEJASH | F10: ='Membership Level'!A3 -> Cricket Month | G10: 2000 | H10: 2000 | J10: 45690 | K10: =DATE(YEAR(J10),MONTH(J10)+VLOOKUP($F10,'Membership Level'!$A$3:$B$10,2,FALSE),DAY(J10)) -> 45718 | L10: 3 | M10: 0 | N10: =IF($K10<>0,DATE(YEAR($K10),MONTH($K10)-$M10,DAY($K10)-$L10),"") -> 45715 | O10: =IF(DAYS360(NOW(), $K10) >= 0, DAYS360(NOW(), $K10), "") | P10: =H10/G10*VLOOKUP(F10,'Membership Level'!$A$3:$C$10,3,FALSE)+J10 -> 45720 | Q10: DUES | R10: 44428 | T10: =5300/3 -> 1766.6667 | U10: 1 MONTH
A11: SINGH | B11: AYUSH | F11: ='Membership Level'!A3 -> Cricket Month | G11: 2000 | H11: 2000 | J11: 45732 | K11: =DATE(YEAR(J11),MONTH(J11)+VLOOKUP($F11,'Membership Level'!$A$3:$B$10,2,FALSE),DAY(J11)) -> 45763 | L11: 3 | M11: 0 | N11: =IF($K11<>0,DATE(YEAR($K11),MONTH($K11)-$M11,DAY($K11)-$L11),"") -> 45760 | O11: =IF(DAYS360(NOW(), $K11) >= 0, DAYS360(NOW(), $K11), "") | P11: =H11/G11*VLOOKUP(F11,'Membership Level'!$A$3:$C$10,3,FALSE)+J11 -> 45762 | Q11: 44754 | T11: 4250
A12: RANJAN | B12: MOURYA | F12: ='Membership Level'!A3 -> Cricket Month | G12: 2000 | H12: 2000 | J12: 45706 | K12: =DATE(YEAR(J12),MONTH(J12)+VLOOKUP($F12,'Membership Level'!$A$3:$B$10,2,FALSE),DAY(J12)) -> 45734 | L12: 3 | M12: 0 | N12: =IF($K12<>0,DATE(YEAR($K12),MONTH($K12)-$M12,DAY($K12)-$L12),"") -> 45731 | O12: =IF(DAYS360(NOW(), $K12) >= 0, DAYS360(NOW(), $K12), "") | P12: =H12/G12*VLOOKUP(F12,'Membership Level'!$A$3:$C$10,3,FALSE)+J12 -> 45736 | Q12: DUES | T12: 2500
A13: SINGH | B13: ABHIMAN | F13: ='Membership Level'!A3 -> Cricket Month | G13: 2000 | H13: 1000 | J13: 45675 | K13: =DATE(YEAR(J13),MONTH(J13)+VLOOKUP($F13,'Membership Level'!$A$3:$B$10,2,FALSE),DAY(J13)) -> 45706 | L13: 3 | M13: 0 | N13: =IF($K13<>0,DATE(YEAR($K13),MONTH($K13)-$M13,DAY($K13)-$L13),"") -> 45703 | O13: =IF(DAYS360(NOW(), $K13) >= 0, DAYS360(NOW(), $K13), "") | P13: =H13/G13*VLOOKUP(F13,'Membership Level'!$A$3:$C$10,3,FALSE)+J13 -> 45690 | T13: 2000 | V13: =3400+850 -> 4250
K14: =DATE(YEAR(J14),MONTH(J14)+VLOOKUP($F14,'Membership Level'!$A$3:$B$10,2,FALSE),DAY(J14)) -> #N/A | L14: 3 | M14: 0 | N14: =IF($K14<>0,DATE(YEAR($K14),MONTH($K14)-$M14,DAY($K14)-$L14),"") -> #N/A | O14: =IF(DAYS360(NOW(), $K14) >= 0, DAYS360(NOW(), $K14), "") -> #N/A | P14: =H14/G14*VLOOKUP(F14,'Membership Level'!$A$3:$C$10,3,FALSE)+J14 -> #DIV/0! | R14: 1-3 TO BE COUNTINEW | T14: 3750
K15: =DATE(YEAR(J15),MONTH(J15)+VLOOKUP($F15,'Membership Level'!$A$3:$B$10,2,FALSE),DAY(J15)) -> #N/A | L15: 3 | M15: 0 | N15: =IF($K15<>0,DATE(YEAR($K15),MONTH($K15)-$M15,DAY($K15)-$L15),"") -> #N/A | O15: =IF(DAYS360(NOW(), $K15) >= 0, DAYS360(NOW(), $K15), "") -> #N/A | P15: =H15/G15*VLOOKUP(F15,'Membership Level'!$A$3:$C$10,3,FALSE)+J15 -> #DIV/0!
K16: =DATE(YEAR(J16),MONTH(J16)+VLOOKUP($F16,'Membership Level'!$A$3:$B$10,2,FALSE),DAY(J16)) -> #N/A | L16: 3 | M16: 0 | N16: =IF($K16<>0,DATE(YEAR($K16),MONTH($K16)-$M16,DAY($K16)-$L16),"") -> #N/A | O16: =IF(DAYS360(NOW(), $K16) >= 0, DAYS360(NOW(), $K16), "") -> #N/A | P16: =H16/G16*VLOOKUP(F16,'Membership Level'!$A$3:$C$10,3,FALSE)+J16 -> #DIV/0! | Q16: DUES
K17: =DATE(YEAR(J17),MONTH(J17)+VLOOKUP($F17,'Membership Level'!$A$3:$B$10,2,FALSE),DAY(J17)) -> #N/A | L17: 3 | M17: 0 | N17: =IF($K17<>0,DATE(YEAR($K17),MONTH($K17)-$M17,DAY($K17)-$L17),"") -> #N/A | O17: =IF(DAYS360(NOW(), $K17) >= 0, DAYS360(NOW(), $K17), "") -> #N/A | P17: =H17/G17*VLOOKUP(F17,'Membership Level'!$A$3:$C$10,3,FALSE)+J17 -> #DIV/0! | Q17: DUES
K18: =DATE(YEAR(J18),MONTH(J18)+VLOOKUP($F18,'Membership Level'!$A$3:$B$10,2,FALSE),DAY(J18)) -> #N/A | L18: 3 | M18: 0 | N18: =IF($K18<>0,DATE(YEAR($K18),MONTH($K18)-$M18,DAY($K18)-$L18),"") -> #N/A | O18: =IF(DAYS360(NOW(), $K18) >= 0, DAYS360(NOW(), $K18), "") -> #N/A | P18: =H18/G18*VLOOKUP(F18,'Membership Level'!$A$3:$C$10,3,FALSE)+J18 -> #DIV/0! | Q18: DUES | T18: 2500
K19: =DATE(YEAR(J19),MONTH(J19)+VLOOKUP($F19,'Membership Level'!$A$3:$B$10,2,FALSE),DAY(J19)) -> #N/A | L19: 3 | M19: 0 | N19: =IF($K19<>0,DATE(YEAR($K19),MONTH($K19)-$M19,DAY($K19)-$L19),"") -> #N/A | O19: =IF(DAYS360(NOW(), $K19) >= 0, DAYS360(NOW(), $K19), "") -> #N/A | P19: =H19/G19*VLOOKUP(F19,'Membership Level'!$A$3:$C$10,3,FALSE)+J19 -> #DIV/0! | Q19: N/A
K20: =DATE(YEAR(J20),MONTH(J20)+VLOOKUP($F20,'Membership Level'!$A$3:$B$10,2,FALSE),DAY(J20)) -> #N/A | L20: 3 | M20: 0 | N20: =IF($K20<>0,DATE(YEAR($K20),MONTH($K20)-$M20,DAY($K20)-$L20),"") -> #N/A | O20: =IF(DAYS360(NOW(), $K20) >= 0, DAYS360(NOW(), $K20), "") -> #N/A | P20: =H20/G20*VLOOKUP(F20,'Membership Level'!$A$3:$C$10,3,FALSE)+J20 -> #DIV/0!
K21: =DATE(YEAR(J21),MONTH(J21)+VLOOKUP($F21,'Membership Level'!$A$3:$B$10,2,FALSE),DAY(J21)) -> #N/A | L21: 3 | M21: 0 | N21: =IF($K21<>0,DATE(YEAR($K21),MONTH($K21)-$M21,DAY($K21)-$L21),"") -> #N/A | O21: =IF(DAYS360(NOW(), $K21) >= 0, DAYS360(NOW(), $K21), "") -> #N/A | P21: =H21/G21*VLOOKUP(F21,'Membership Level'!$A$3:$C$10,3,FALSE)+J21 -> #DIV/0! | Q21: SEP-9,OCT-15,NOV-12 DAYS | T21: 4500
K22: =DATE(YEAR(J22),MONTH(J22)+VLOOKUP($F22,'Membership Level'!$A$3:$B$10,2,FALSE),DAY(J22)) -> #N/A | L22: 3 | M22: 0 | N22: =IF($K22<>0,DATE(YEAR($K22),MONTH($K22)-$M22,DAY($K22)-$L22),"") -> #N/A | O22: =IF(DAYS360(NOW(), $K22) >= 0, DAYS360(NOW(), $K22), "") -> #N/A | P22: =H22/G22*VLOOKUP(F22,'Membership Level'!$A$3:$C$10,3,FALSE)+J22 -> #DIV/0! | Q22: DUES | R22: 44423 | T22: 2500
K23: =DATE(YEAR(J23),MONTH(J23)+VLOOKUP($F23,'Membership Level'!$A$3:$B$10,2,FALSE),DAY(J23)) -> #N/A | L23: 3 | M23: 0 | N23: =IF($K23<>0,DATE(YEAR($K23),MONTH($K23)-$M23,DAY($K23)-$L23),"") -> #N/A | O23: =IF(DAYS360(NOW(), $K23) >= 0, DAYS360(NOW(), $K23), "") -> #N/A | P23: =H23/G23*VLOOKUP(F23,'Membership Level'!$A$3:$C$10,3,FALSE)+J23 -> #DIV/0!
K24: =DATE(YEAR(J24),MONTH(J24)+VLOOKUP($F24,'Membership Level'!$A$3:$B$10,2,FALSE),DAY(J24)) -> #N/A | L24: 3 | M24: 0 | N24: =IF($K24<>0,DATE(YEAR($K24),MONTH($K24)-$M24,DAY($K24)-$L24),"") -> #N/A | O24: =IF(DAYS360(NOW(), $K24) >= 0, DAYS360(NOW(), $K24), "") -> #N/A | P24: =H24/G24*VLOOKUP(F24,'Membership Level'!$A$3:$C$10,3,FALSE)+J24 -> #DIV/0! | R24: 44448
K25: =DATE(YEAR(J25),MONTH(J25)+VLOOKUP($F25,'Membership Level'!$A$3:$B$10,2,FALSE),DAY(J25)) -> #N/A | L25: 3 | M25: 0 | N25: =IF($K25<>0,DATE(YEAR($K25),MONTH($K25)-$M25,DAY($K25)-$L25),"") -> #N/A | O25: =IF(DAYS360(NOW(), $K25) >= 0, DAYS360(NOW(), $K25), "") -> #N/A | P25: =H25/G25*VLOOKUP(F25,'Membership Level'!$A$3:$C$10,3,FALSE)+J25 -> #DIV/0!
K26: =DATE(YEAR(J26),MONTH(J26)+VLOOKUP($F26,'Membership Level'!$A$3:$B$10,2,FALSE),DAY(J26)) -> #N/A | L26: 3 | M26: 0 | N26: =IF($K26<>0,DATE(YEAR($K26),MONTH($K26)-$M26,DAY($K26)-$L26),"") -> #N/A | O26: =IF(DAYS360(NOW(), $K26) >= 0, DAYS360(NOW(), $K26), "") -> #N/A | P26: =H26/G26*VLOOKUP(F26,'Membership Level'!$A$3:$C$10,3,FALSE)+J26 -> #DIV/0! | Q26: MAZER ACEDENT
K27: =DATE(YEAR(J27),MONTH(J27)+VLOOKUP($F27,'Membership Level'!$A$3:$B$10,2,FALSE),DAY(J27)) -> #N/A | L27: 3 | M27: 0 | N27: =IF($K27<>0,DATE(YEAR($K27),MONTH($K27)-$M27,DAY($K27)-$L27),"") -> #N/A | O27: =IF(DAYS360(NOW(), $K27) >= 0, DAYS360(NOW(), $K27), "") -> #N/A | P27: =H27/G27*VLOOKUP(F27,'Membership Level'!$A$3:$C$10,3,FALSE)+J27 -> #DIV/0!
K28: =DATE(YEAR(J28),MONTH(J28)+VLOOKUP($F28,'Membership Level'!$A$3:$B$10,2,FALSE),DAY(J28)) -> #N/A | L28: 3 | M28: 0 | N28: =IF($K28<>0,DATE(YEAR($K28),MONTH($K28)-$M28,DAY($K28)-$L28),"") -> #N/A | O28: =IF(DAYS360(NOW(), $K28) >= 0, DAYS360(NOW(), $K28), "") -> #N/A | P28: =H28/G28*VLOOKUP(F28,'Membership Level'!$A$3:$C$10,3,FALSE)+J28 -> #DIV/0! | Q28: DUES
K29: =DATE(YEAR(J29),MONTH(J29)+VLOOKUP($F29,'Membership Level'!$A$3:$B$10,2,FALSE),DAY(J29)) -> #N/A | L29: 3 | M29: 0 | N29: =IF($K29<>0,DATE(YEAR($K29),MONTH($K29)-$M29,DAY($K29)-$L29),"") -> #N/A | O29: =IF(DAYS360(NOW(), $K29) >= 0, DAYS360(NOW(), $K29), "") -> #N/A | P29: =H29/G29*VLOOKUP(F29,'Membership Level'!$A$3:$C$10,3,FALSE)+J29 -> #DIV/0! | Q29: SUNDAY/TUESDAY
K30: =DATE(YEAR(J30),MONTH(J30)+VLOOKUP($F30,'Membership Level'!$A$3:$B$10,2,FALSE),DAY(J30)) -> #N/A | L30: 3 | M30: 0 | N30: =IF($K30<>0,DATE(YEAR($K30),MONTH($K30)-$M30,DAY($K30)-$L30),"") -> #N/A | O30: =IF(DAYS360(NOW(), $K30) >= 0, DAYS360(NOW(), $K30), "") -> #N/A | P30: =H30/G30*VLOOKUP(F30,'Membership Level'!$A$3:$C$10,3,FALSE)+J30 -> #DIV/0! | Q30: 44752 | R30: 3000
K31: =DATE(YEAR(J31),MONTH(J31)+VLOOKUP($F31,'Membership Level'!$A$3:$B$10,2,FALSE),DAY(J31)) -> #N/A | L31: 3 | M31: 0 | N31: =IF($K31<>0,DATE(YEAR($K31),MONTH($K31)-$M31,DAY($K31)-$L31),"") -> #N/A | O31: =IF(DAYS360(NOW(), $K31) >= 0, DAYS360(NOW(), $K31), "") -> #N/A | P31: =H31/G31*VLOOKUP(F31,'Membership Level'!$A$3:$C$10,3,FALSE)+J31 -> #DIV/0! | Q31: NEXT WEEK | R31: 3 MONTH COVID EXT.(MAY+JUNE+FEB | S31: 3000
K32: =DATE(YEAR(J32),MONTH(J32)+VLOOKUP($F32,'Membership Level'!$A$3:$B$10,2,FALSE),DAY(J32)) -> #N/A | L32: 3 | M32: 0 | N32: =IF($K32<>0,DATE(YEAR($K32),MONTH($K32)-$M32,DAY($K32)-$L32),"") -> #N/A | O32: =IF(DAYS360(NOW(), $K32) >= 0, DAYS360(NOW(), $K32), "") -> #N/A | P32: =H32/G32*VLOOKUP(F32,'Membership Level'!$A$3:$C$10,3,FALSE)+J32 -> #DIV/0!
K33: =DATE(YEAR(J33),MONTH(J33)+VLOOKUP($F33,'Membership Level'!$A$3:$B$10,2,FALSE),DAY(J33)) -> #N/A | L33: 3 | M33: 0 | N33: =IF($K33<>0,DATE(YEAR($K33),MONTH($K33)-$M33,DAY($K33)-$L33),"") -> #N/A | O33: =IF(DAYS360(NOW(), $K33) >= 0, DAYS360(NOW(), $K33), "") -> #N/A | P33: =H33/G33*VLOOKUP(F33,'Membership Level'!$A$3:$C$10,3,FALSE)+J33 -> #DIV/0!
K34: =J34+90 -> 90 | L34: 3 | M34: 0 | N34: =IF($K34<>0,DATE(YEAR($K34),MONTH($K34)-$M34,DAY($K34)-$L34),"") -> 87 | O34: =IF(DAYS360(NOW(), $K34) >= 0, DAYS360(NOW(), $K34), "") | P34: =H34/G34*VLOOKUP(F34,'Membership Level'!$A$3:$C$10,3,FALSE)+J34 -> #DIV/0! | Q34: COMING WEEK
K35: =DATE(YEAR(J35),MONTH(J35)+VLOOKUP($F35,'Membership Level'!$A$3:$B$10,2,FALSE),DAY(J35)) -> #N/A | L35: 3 | M35: 0 | N35: =IF($K35<>0,DATE(YEAR($K35),MONTH($K35)-$M35,DAY($K35)-$L35),"") -> #N/A | O35: =IF(DAYS360(NOW(), $K35) >= 0, DAYS360(NOW(), $K35), "") -> #N/A | P35: =H35/G35*VLOOKUP(F35,'Membership Level'!$A$3:$C$10,3,FALSE)+J35 -> #DIV/0!
K36: =DATE(YEAR(J36),MONTH(J36)+VLOOKUP($F36,'Membership Level'!$A$3:$B$10,2,FALSE),DAY(J36)) -> #N/A | L36: 3 | M36: 0 | N36: =IF($K36<>0,DATE(YEAR($K36),MONTH($K36)-$M36,DAY($K36)-$L36),"") -> #N/A | O36: =IF(DAYS360(NOW(), $K36) >= 0, DAYS360(NOW(), $K36), "") -> #N/A | P36: =H36/G36*VLOOKUP(F36,'Membership Level'!$A$3:$C$10,3,FALSE)+J36 -> #DIV/0!
K37: =DATE(YEAR(J37),MONTH(J37)+VLOOKUP($F37,'Membership Level'!$A$3:$B$10,2,FALSE),DAY(J37)) -> #N/A | L37: 3 | M37: 0 | N37: =IF($K37<>0,DATE(YEAR($K37),MONTH($K37)-$M37,DAY($K37)-$L37),"") -> #N/A | O37: =IF(DAYS360(NOW(), $K37) >= 0, DAYS360(NOW(), $K37), "") -> #N/A | P37: =H37/G37*VLOOKUP(F37,'Membership Level'!$A$3:$C$10,3,FALSE)+J37 -> #DIV/0!
K38: =DATE(YEAR(J38),MONTH(J38)+VLOOKUP($F38,'Membership Level'!$A$3:$B$10,2,FALSE),DAY(J38)) -> #N/A | L38: 3 | M38: 0 | N38: =IF($K38<>0,DATE(YEAR($K38),MONTH($K38)-$M38,DAY($K38)-$L38),"") -> #N/A | O38: =IF(DAYS360(NOW(), $K38) >= 0, DAYS360(NOW(), $K38), "") -> #N/A | P38: =H38/G38*VLOOKUP(F38,'Membership Level'!$A$3:$C$10,3,FALSE)+J38 -> #DIV/0!
K39: =DATE(YEAR(J39),MONTH(J39)+VLOOKUP($F39,'Membership Level'!$A$3:$B$10,2,FALSE),DAY(J39)) -> #N/A | L39: 3 | M39: 0 | N39: =IF($K39<>0,DATE(YEAR($K39),MONTH($K39)-$M39,DAY($K39)-$L39),"") -> #N/A | O39: =IF(DAYS360(NOW(), $K39) >= 0, DAYS360(NOW(), $K39), "") -> #N/A | P39: =H39/G39*VLOOKUP(F39,'Membership Level'!$A$3:$C$10,3,FALSE)+J39 -> #DIV/0!
K40: =DATE(YEAR(J40),MONTH(J40)+VLOOKUP($F40,'Membership Level'!$A$3:$B$10,2,FALSE),DAY(J40)) -> #N/A | L40: 3 | M40: 0 | N40: =IF($K40<>0,DATE(YEAR($K40),MONTH($K40)-$M40,DAY($K40)-$L40),"") -> #N/A | O40: =IF(DAYS360(NOW(), $K40) >= 0, DAYS360(NOW(), $K40), "") -> #N/A | P40: =H40/G40*VLOOKUP(F40,'Membership Level'!$A$3:$C$10,3,FALSE)+J40 -> #DIV/0!
K41: =DATE(YEAR(J41),MONTH(J41)+VLOOKUP($F41,'Membership Level'!$A$3:$B$10,2,FALSE),DAY(J41)) -> #N/A | L41: 3 | M41: 0 | N41: =IF($K41<>0,DATE(YEAR($K41),MONTH($K41)-$M41,DAY($K41)-$L41),"") -> #N/A | O41: =IF(DAYS360(NOW(), $K41) >= 0, DAYS360(NOW(), $K41), "") -> #N/A | P41: =H41/G41*VLOOKUP(F41,'Membership Level'!$A$3:$C$10,3,FALSE)+J41 -> #DIV/0!
K42: =DATE(YEAR(J42),MONTH(J42)+VLOOKUP($F42,'Membership Level'!$A$3:$B$10,2,FALSE),DAY(J42)) -> #N/A | L42: 3 | M42: 0 | N42: =IF($K42<>0,DATE(YEAR($K42),MONTH($K42)-$M42,DAY($K42)-$L42),"") -> #N/A | O42: =IF(DAYS360(NOW(), $K42) >= 0, DAYS360(NOW(), $K42), "") -> #N/A | P42: =H42/G42*VLOOKUP(F42,'Membership Level'!$A$3:$C$10,3,FALSE)+J42 -> #DIV/0!
K43: =DATE(YEAR(J43),MONTH(J43)+VLOOKUP($F43,'Membership Level'!$A$3:$B$10,2,FALSE),DAY(J43)) -> #N/A | L43: 3 | M43: 0 | N43: =IF($K43<>0,DATE(YEAR($K43),MONTH($K43)-$M43,DAY($K43)-$L43),"") -> #N/A | O43: =IF(DAYS360(NOW(), $K43) >= 0, DAYS360(NOW(), $K43), "") -> #N/A | P43: =H43/G43*VLOOKUP(F43,'Membership Level'!$A$3:$C$10,3,FALSE)+J43 -> #DIV/0!
K44: =DATE(YEAR(J44),MONTH(J44)+VLOOKUP($F44,'Membership Level'!$A$3:$B$10,2,FALSE),DAY(J44)) -> #N/A | L44: 3 | M44: 0 | N44: =IF($K44<>0,DATE(YEAR($K44),MONTH($K44)-$M44,DAY($K44)-$L44),"") -> #N/A | O44: =IF(DAYS360(NOW(), $K44) >= 0, DAYS360(NOW(), $K44), "") -> #N/A | P44: =H44/G44*VLOOKUP(F44,'Membership Level'!$A$3:$C$10,3,FALSE)+J44 -> #DIV/0!
...

Sheet ZUMBA
F2: ZUMBA
A7: Contact Information | E7: Membership | K7: Notice term
A8: Name | B8: Address | C8: Email | D8: Phone | E8: Level | F8: Membership Fees | G8: Fees Paid | H8: Fees Due | I8: Start | J8: Expiration | K8: Days | L8: Month | M8: Termination Notice | N8: Days To Expiration | O8: Pending Fee Notice | P8: Notes
A9: SINGH | B9: NEHA | E9: ='Membership Level'!A18 -> Zumba Month | F9: 1500 | G9: 1500 | H9: =F9-G9 -> 0 | I9: 45711 | J9: =I9+30 -> 45741 | K9: 3 | L9: 0 | M9: =IF($J9<>0,DATE(YEAR($J9),MONTH($J9)-$L9,DAY($J9)-$K9),"") -> 45738 | N9: =IF(DAYS360(NOW(), $J9) >= 0, DAYS360(NOW(), $J9), "") | O9: =G9/F9*VLOOKUP(E9,'Membership Level'!$A$3:$C$10,3,FALSE)+I9 -> #N/A
B10: NILAM | E10: ='Membership Level'!A18 -> Zumba Month | F10: 1500 | G10: 1500 | H10: =F10-G10 -> 0 | I10: 45717 | J10: =I10+30 -> 45747 | K10: 3 | M10: =IF($J10<>0,DATE(YEAR($J10),MONTH($J10)-$L10,DAY($J10)-$K10),"") -> 45744 | N10: =IF(DAYS360(NOW(), $J10) >= 0, DAYS360(NOW(), $J10), "") | O10: =G10/F10*VLOOKUP(E10,'Membership Level'!$A$3:$C$10,3,FALSE)+I10 -> #N/A
B11: SHALINI | E11: ='Membership Level'!A18 -> Zumba Month | F11: 1500 | G11: 1500 | H11: =F11-G11 -> 0 | I11: 45689 | J11: =I11+30 -> 45719 | K11: 3 | M11: =IF($J11<>0,DATE(YEAR($J11),MONTH($J11)-$L11,DAY($J11)-$K11),"") -> 45716 | N11: =IF(DAYS360(NOW(), $J11) >= 0, DAYS360(NOW(), $J11), "") | O11: =G11/F11*VLOOKUP(E11,'Membership Level'!$A$3:$C$10,3,FALSE)+I11 -> #N/A
A12: KATORE | B12: KANCHAN | E12: ='Membership Level'!A18 -> Zumba Month | F12: 1500 | G12: 1500 | H12: =F12-G12 -> 0 | I12: 45734 | J12: =I12+30 -> 45764 | K12: 3 | M12: =IF($J12<>0,DATE(YEAR($J12),MONTH($J12)-$L12,DAY($J12)-$K12),"") -> 45761 | N12: =IF(DAYS360(NOW(), $J12) >= 0, DAYS360(NOW(), $J12), "") | O12: =G12/F12*VLOOKUP(E12,'Membership Level'!$A$3:$C$10,3,FALSE)+I12 -> #N/A
A13: DANKAR | B13: ANUPAMA | E13: ='Membership Level'!A18 -> Zumba Month | F13: 1500 | G13: 1500 | H13: =F13-G13 -> 0 | I13: 45707 | J13: =I13+30 -> 45737 | K13: 3 | M13: =IF($J13<>0,DATE(YEAR($J13),MONTH($J13)-$L13,DAY($J13)-$K13),"") -> 45734 | N13: =IF(DAYS360(NOW(), $J13) >= 0, DAYS360(NOW(), $J13), "") | O13: =G13/F13*VLOOKUP(E13,'Membership Level'!$A$3:$C$10,3,FALSE)+I13 -> #N/A
B14: SWETA | E14: ='Membership Level'!A18 -> Zumba Month | F14: 1500 | G14: 1500 | H14: =F14-G14 -> 0 | I14: 45709 | J14: =I14+30 -> 45739 | K14: 3 | M14: =IF($J14<>0,DATE(YEAR($J14),MONTH($J14)-$L14,DAY($J14)-$K14),"") -> 45736 | N14: =IF(DAYS360(NOW(), $J14) >= 0, DAYS360(NOW(), $J14), "") | O14: =G14/F14*VLOOKUP(E14,'Membership Level'!$A$3:$C$10,3,FALSE)+I14 -> #N/A
B15: SWATI | E15: ='Membership Level'!A18 -> Zumba Month | F15: 800 | G15: 800 | H15: =F15-G15 -> 0 | I15: 45690 | J15: =I15+30 -> 45720 | K15: 3 | M15: =IF($J15<>0,DATE(YEAR($J15),MONTH($J15)-$L15,DAY($J15)-$K15),"") -> 45717 | N15: =IF(DAYS360(NOW(), $J15) >= 0, DAYS360(NOW(), $J15), "") | O15: =G15/F15*VLOOKUP(E15,'Membership Level'!$A$3:$C$10,3,FALSE)+I15 -> #N/A
H16: =F16-G16 -> 0 | I16: 45026 | J16: =I16+30 -> 45056 | K16: 3 | M16: =IF($J16<>0,DATE(YEAR($J16),MONTH($J16)-$L16,DAY($J16)-$K16),"") -> 45053 | N16: =IF(DAYS360(NOW(), $J16) >= 0, DAYS360(NOW(), $J16), "") | O16: =G16/F16*VLOOKUP(E16,'Membership Level'!$A$3:$C$10,3,FALSE)+I16 -> #DIV/0!
H17: =F17-G17 -> 0 | I17: 45296 | J17: 45327 | K17: 3 | M17: =IF($J17<>0,DATE(YEAR($J17),MONTH($J17)-$L17,DAY($J17)-$K17),"") -> 45324 | N17: =IF(DAYS360(NOW(), $J17) >= 0, DAYS360(NOW(), $J17), "") | O17: =G17/F17*VLOOKUP(E17,'Membership Level'!$A$3:$C$10,3,FALSE)+I17 -> #DIV/0!
H18: =F18-G18 -> 0 | I18: 44986 | J18: =I18+90 -> 45076 | K18: 3 | M18: =IF($J18<>0,DATE(YEAR($J18),MONTH($J18)-$L18,DAY($J18)-$K18),"") -> 45073 | N18: =IF(DAYS360(NOW(), $J18) >= 0, DAYS360(NOW(), $J18), "") | O18: =G18/F18*VLOOKUP(E18,'Membership Level'!$A$3:$C$10,3,FALSE)+I18 -> #DIV/0!
H19: =F19-G19 -> 0 | I19: 45292 | J19: 45323 | K19: 3 | M19: =IF($J19<>0,DATE(YEAR($J19),MONTH($J19)-$L19,DAY($J19)-$K19),"") -> 45320 | N19: =IF(DAYS360(NOW(), $J19) >= 0, DAYS360(NOW(), $J19), "") | O19: =G19/F19*VLOOKUP(E19,'Membership Level'!$A$3:$C$10,3,FALSE)+I19 -> #DIV/0!
H20: =F20-G20 -> 0 | I20: 45034 | J20: =I20+30 -> 45064 | K20: 3 | M20: =IF($J20<>0,DATE(YEAR($J20),MONTH($J20)-$L20,DAY($J20)-$K20),"") -> 45061 | N20: =IF(DAYS360(NOW(), $J20) >= 0, DAYS360(NOW(), $J20), "") | O20: =G20/F20*VLOOKUP(E20,'Membership Level'!$A$3:$C$10,3,FALSE)+I20 -> #DIV/0!
H21: =F21-G21 -> 0 | I21: 45057 | J21: =I21+30 -> 45087 | K21: 3 | M21: =IF($J21<>0,DATE(YEAR($J21),MONTH($J21)-$L21,DAY($J21)-$K21),"") -> 45084 | N21: =IF(DAYS360(NOW(), $J21) >= 0, DAYS360(NOW(), $J21), "") | O21: =G21/F21*VLOOKUP(E21,'Membership Level'!$A$3:$C$10,3,FALSE)+I21 -> #DIV/0!
H22: =F22-G22 -> 0 | I22: 45059 | J22: =I22+30 -> 45089 | K22: 3 | M22: =IF($J22<>0,DATE(YEAR($J22),MONTH($J22)-$L22,DAY($J22)-$K22),"") -> 45086 | N22: =IF(DAYS360(NOW(), $J22) >= 0, DAYS360(NOW(), $J22), "") | O22: =G22/F22*VLOOKUP(E22,'Membership Level'!$A$3:$C$10,3,FALSE)+I22 -> #DIV/0!
H23: =F23-G23 -> 0 | I23: 45225 | J23: =I23+30 -> 45255 | K23: 3 | M23: =IF($J23<>0,DATE(YEAR($J23),MONTH($J23)-$L23,DAY($J23)-$K23),"") -> 45252 | N23: =IF(DAYS360(NOW(), $J23) >= 0, DAYS360(NOW(), $J23), "") | O23: =G23/F23*VLOOKUP(E23,'Membership Level'!$A$3:$C$10,3,FALSE)+I23 -> #DIV/0!
H24: =F24-G24 -> 0 | I24: 45097 | J24: =I24+30 -> 45127 | K24: 3 | M24: =IF($J24<>0,DATE(YEAR($J24),MONTH($J24)-$L24,DAY($J24)-$K24),"") -> 45124 | N24: =IF(DAYS360(NOW(), $J24) >= 0, DAYS360(NOW(), $J24), "") | O24: =G24/F24*VLOOKUP(E24,'Membership Level'!$A$3:$C$10,3,FALSE)+I24 -> #DIV/0!
H25: =F25-G25 -> 0 | I25: 45076 | J25: =I25+30 -> 45106 | K25: 3 | M25: =IF($J25<>0,DATE(YEAR($J25),MONTH($J25)-$L25,DAY($J25)-$K25),"") -> 45103 | N25: =IF(DAYS360(NOW(), $J25) >= 0, DAYS360(NOW(), $J25), "") | O25: =G25/F25*VLOOKUP(E25,'Membership Level'!$A$3:$C$10,3,FALSE)+I25 -> #DIV/0!
H26: =F26-G26 -> 0 | I26: 45085 | J26: =I26+30 -> 45115 | K26: 3 | M26: =IF($J26<>0,DATE(YEAR($J26),MONTH($J26)-$L26,DAY($J26)-$K26),"") -> 45112 | N26: =IF(DAYS360(NOW(), $J26) >= 0, DAYS360(NOW(), $J26), "") | O26: =G26/F26*VLOOKUP(E26,'Membership Level'!$A$3:$C$10,3,FALSE)+I26 -> #DIV/0!
H27: =F27-G27 -> 0 | I27: 45115 | J27: =I27+90 -> 45205 | K27: 3 | M27: =IF($J27<>0,DATE(YEAR($J27),MONTH($J27)-$L27,DAY($J27)-$K27),"") -> 45202 | N27: =IF(DAYS360(NOW(), $J27) >= 0, DAYS360(NOW(), $J27), "") | O27: =G27/F27*VLOOKUP(E27,'Membership Level'!$A$3:$C$10,3,FALSE)+I27 -> #DIV/0!
H28: =F28-G28 -> 0 | I28: 45274 | J28: =I28+30 -> 45304 | K28: 3 | M28: =IF($J28<>0,DATE(YEAR($J28),MONTH($J28)-$L28,DAY($J28)-$K28),"") -> 45301 | N28: =IF(DAYS360(NOW(), $J28) >= 0, DAYS360(NOW(), $J28), "") | O28: =G28/F28*VLOOKUP(E28,'Membership Level'!$A$3:$C$10,3,FALSE)+I28 -> #DIV/0!
H29: =F29-G29 -> 0 | I29: 45261 | J29: 45292 | K29: 3 | M29: =IF($J29<>0,DATE(YEAR($J29),MONTH($J29)-$L29,DAY($J29)-$K29),"") -> 45289 | N29: =IF(DAYS360(NOW(), $J29) >= 0, DAYS360(NOW(), $J29), "") | O29: =G29/F29*VLOOKUP(E29,'Membership Level'!$A$3:$C$10,3,FALSE)+I29 -> #DIV/0!
H30: =F30-G30 -> 0 | I30: 45110 | J30: =I30+30 -> 45140 | K30: 3 | M30: =IF($J30<>0,DATE(YEAR($J30),MONTH($J30)-$L30,DAY($J30)-$K30),"") -> 45137 | N30: =IF(DAYS360(NOW(), $J30) >= 0, DAYS360(NOW(), $J30), "") | O30: =G30/F30*VLOOKUP(E30,'Membership Level'!$A$3:$C$10,3,FALSE)+I30 -> #DIV/0!
H31: =F31-G31 -> 0 | I31: 45111 | J31: =I31+30 -> 45141 | K31: 3 | M31: =IF($J31<>0,DATE(YEAR($J31),MONTH($J31)-$L31,DAY($J31)-$K31),"") -> 45138 | N31: =IF(DAYS360(NOW(), $J31) >= 0, DAYS360(NOW(), $J31), "") | O31: =G31/F31*VLOOKUP(E31,'Membership Level'!$A$3:$C$10,3,FALSE)+I31 -> #DIV/0!
H32: =F32-G32 -> 0 | I32: 45173 | J32: =I32+30 -> 45203 | K32: 3 | M32: =IF($J32<>0,DATE(YEAR($J32),MONTH($J32)-$L32,DAY($J32)-$K32),"") -> 45200 | N32: =IF(DAYS360(NOW(), $J32) >= 0, DAYS360(NOW(), $J32), "") | O32: =G32/F32*VLOOKUP(E32,'Membership Level'!$A$3:$C$10,3,FALSE)+I32 -> #DIV/0!
H33: =F33-G33 -> 0 | I33: 45200 | J33: =I33+30 -> 45230 | K33: 3 | M33: =IF($J33<>0,DATE(YEAR($J33),MONTH($J33)-$L33,DAY($J33)-$K33),"") -> 45227 | N33: =IF(DAYS360(NOW(), $J33) >= 0, DAYS360(NOW(), $J33), "") | O33: =G33/F33*VLOOKUP(E33,'Membership Level'!$A$3:$C$10,3,FALSE)+I33 -> #DIV/0!
H34: =F34-G34 -> 0 | I34: 45143 | J34: =I34+30 -> 45173 | K34: 3 | M34: =IF($J34<>0,DATE(YEAR($J34),MONTH($J34)-$L34,DAY($J34)-$K34),"") -> 45170 | N34: =IF(DAYS360(NOW(), $J34) >= 0, DAYS360(NOW(), $J34), "") | O34: =G34/F34*VLOOKUP(E34,'Membership Level'!$A$3:$C$10,3,FALSE)+I34 -> #DIV/0!
H35: =F35-G35 -> 0 | I35: 45273 | J35: =I35+30 -> 45303 | K35: 3 | M35: =IF($J35<>0,DATE(YEAR($J35),MONTH($J35)-$L35,DAY($J35)-$K35),"") -> 45300 | N35: =IF(DAYS360(NOW(), $J35) >= 0, DAYS360(NOW(), $J35), "") | O35: =G35/F35*VLOOKUP(E35,'Membership Level'!$A$3:$C$10,3,FALSE)+I35 -> #DIV/0!
H36: =F36-G36 -> 0 | I36: 45294 | J36: =I36+30 -> 45324 | K36: 3 | M36: =IF($J36<>0,DATE(YEAR($J36),MONTH($J36)-$L36,DAY($J36)-$K36),"") -> 45321 | N36: =IF(DAYS360(NOW(), $J36) >= 0, DAYS360(NOW(), $J36), "") | O36: =G36/F36*VLOOKUP(E36,'Membership Level'!$A$3:$C$10,3,FALSE)+I36 -> #DIV/0!
H37: =F37-G37 -> 0 | K37: 3 | M37: =IF($J37<>0,DATE(YEAR($J37),MONTH($J37)-$L37,DAY($J37)-$K37),"") | O37: =G37/F37*VLOOKUP(E37,'Membership Level'!$A$3:$C$10,3,FALSE)+I37 -> #DIV/0!
H38: =F38-G38 -> 0 | K38: 3 | M38: =IF($J38<>0,DATE(YEAR($J38),MONTH($J38)-$L38,DAY($J38)-$K38),"") | O38: =G38/F38*VLOOKUP(E38,'Membership Level'!$A$3:$C$10,3,FALSE)+I38 -> #DIV/0!
K39: 3 | M39: =IF($J39<>0,DATE(YEAR($J39),MONTH($J39)-$L39,DAY($J39)-$K39),"") | O39: =G39/F39*VLOOKUP(E39,'Membership Level'!$A$3:$C$10,3,FALSE)+I39 -> #DIV/0!
K40: 3 | M40: =IF($J40<>0,DATE(YEAR($J40),MONTH($J40)-$L40,DAY($J40)-$K40),"") | O40: =G40/F40*VLOOKUP(E40,'Membership Level'!$A$3:$C$10,3,FALSE)+I40 -> #DIV/0!
K41: 3 | M41: =IF($J41<>0,DATE(YEAR($J41),MONTH($J41)-$L41,DAY($J41)-$K41),"") | O41: =G41/F41*VLOOKUP(E41,'Membership Level'!$A$3:$C$10,3,FALSE)+I41 -> #DIV/0!
K42: 3 | M42: =IF($J42<>0,DATE(YEAR($J42),MONTH($J42)-$L42,DAY($J42)-$K42),"")
K43: 3 | M43: =IF($J43<>0,DATE(YEAR($J43),MONTH($J43)-$L43,DAY($J43)-$K43),"")
M44: =IF($J44<>0,DATE(YEAR($J44),MONTH($J44)-$L44,DAY($J44)-$K44),"")
M45: =IF($J45<>0,DATE(YEAR($J45),MONTH($J45)-$L45,DAY($J45)-$K45),"")
...
