Workbook

Sheet Membership Level
A2: Levels | B2: Duration (Months) | C2: DAYS
A3: Cricket Month | B3: 1 | C3: =30*B3
A4: Cricket Qty | B4: 3 | C4: =30*B4
A5: Cricket HY | B5: 6 | C5: =30*B5
A6: Cricket Y | B6: 12 | C6: =30*B6
A7: Tennis Moth | B7: 1 | C7: =30*B7
A8: Tennis Qty | B8: 3 | C8: =30*B8
A9: Tennis HY | B9: 6 | C9: =30*B9
A10: Tennis Y | B10: 12 | C10: =30*B10
A11: Swimming 2 Moth | B11: 2 | C11: =30*B11
A12: Swimming Moth | B12: 1 | C12: =30*B12
A13: Swimming Qty | B13: 3 | C13: =30*B13
A14: Swimming HY | B14: 6 | C14: =30*B14
... A19: ZUMBA QTY | B19: 3 | C19: =30*B19
A20: SKATING MONTH | B20: 1 | C20: 30
A21: SKATING QTY | B21: 3 | C21: 90
F39: ='Membership Level'!A1

Sheet Sheet1

Sheet SWIMMING 2026
D2: Club Membership Database | E2: -2026
C5: =3300*30/100
A7: Contact Information | F7: Membership | M7: Notice term
A8: REG NO | B8: REG, DATE | C8: Last Name | D8: First Name | E8: MOBILE NO. | F8: Level | G8: DAYS | H8: Membership Fees | I8: Fees Paid | J8: Fees Due | K8: Start | L8: Expiration | M8: Days | N8: Termination Notice | O8: Days To Expiration | P8: Pending Fee Notice | Q8: REMARKS
A9: CAP/SW/398 | B9: 46127 | C9: GAURAV | D9: JEETENDRA | E9: 9122516151 | F9: ='Membership Level'!A12 | G9: MONTHLY | H9: 3300 | I9: 3300 | J9: =IF(H9="","",H9-I9) | K9: 46127 | L9: =IF(OR(K9="",$F9=""),"",DATE(YEAR(K9),MONTH(K9)+VLOOKUP($F9,'Membership Level'!$A$3:$B$15,2,FALSE),DAY(K9))) | M9: 3 | N9: =IF($L9="","",DATE(YEAR($L9),MONTH($L9),DAY($L9)-$M9)) | O9: =IF($L9="","",IF(DAYS360(NOW(),$L9)>=0,DAYS360(NOW(),$L9),"")) | P9: =IF(OR(H9="",H9=0,F9="",K9=""),"",I9/H9*VLOOKUP(F9,'Membership Level'!$A$3:$C$15,3,FALSE)+K9)
A10: CAP/SW/399 | B10: 46127 | C10: SAWARN | D10: RUDRANSH | E10: 9899582476 | F10: ='Membership Level'!A12 | G10: MONTHLY | H10: 3500 | I10: 3500 | J10: =IF(H10="","",H10-I10) | K10: 46127 | L10: =IF(OR(K10="",$F10=""),"",DATE(YEAR(K10),MONTH(K10)+VLOOKUP($F10,'Membership Level'!$A$3:$B$15,2,FALSE),DAY(K10))) | M10: 3 | N10: =IF($L10="","",DATE(YEAR($L10),MONTH($L10),DAY($L10)-$M10)) | O10: =IF($L10="","",IF(DAYS360(NOW(),$L10)>=0,DAYS360(NOW(),$L10),"")) | P10: =IF(OR(H10="",H10=0,F10="",K10=""),"",I10/H10*VLOOKUP(F10,'Membership Level'!$A$3:$C$15,3,FALSE)+K10)
A11: CAP/SW/400 | B11: 46127 | C11: SAWARN | D11: ANUSHKA | E11: 9899582476 | F11: ='Membership Level'!A12 | G11: MONTHLY | H11: 4000 | I11: 4000 | J11: =IF(H11="","",H11-I11) | K11: 46127 | L11: =IF(OR(K11="",$F11=""),"",DATE(YEAR(K11),MONTH(K11)+VLOOKUP($F11,'Membership Level'!$A$3:$B$15,2,FALSE),DAY(K11))) | M11: 3 | N11: =IF($L11="","",DATE(YEAR($L11),MONTH($L11),DAY($L11)-$M11)) | O11: =IF($L11="","",IF(DAYS360(NOW(),$L11)>=0,DAYS360(NOW(),$L11),"")) | P11: =IF(OR(H11="",H11=0,F11="",K11=""),"",I11/H11*VLOOKUP(F11,'Membership Level'!$A$3:$C$15,3,FALSE)+K11)
A12: CAP/SW/401 | B12: 46127 | C12: SAWARN | D12: PUSHKAR | E12: 9899582476 | F12: ='Membership Level'!A12 | G12: MONTHLY | H12: 4000 | I12: 4000 | J12: =IF(H12="","",H12-I12) | K12: 46127 | L12: =IF(OR(K12="",$F12=""),"",DATE(YEAR(K12),MONTH(K12)+VLOOKUP($F12,'Membership Level'!$A$3:$B$15,2,FALSE),DAY(K12))) | M12: 3 | N12: =IF($L12="","",DATE(YEAR($L12),MONTH($L12),DAY($L12)-$M12)) | O12: =IF($L12="","",IF(DAYS360(NOW(),$L12)>=0,DAYS360(NOW(),$L12),"")) | P12: =IF(OR(H12="",H12=0,F12="",K12=""),"",I12/H12*VLOOKUP(F12,'Membership Level'!$A$3:$C$15,3,FALSE)+K12)
A13: CAP/SW/402 | B13: 46127 | C13: THAPA | D13: AYUSHMAN | E13: 8210438591 | F13: ='Membership Level'!A12 | G13: MONTHLY | H13: 3500 | I13: 3500 | J13: =IF(H13="","",H13-I13) | K13: 46127 | L13: =IF(OR(K13="",$F13=""),"",DATE(YEAR(K13),MONTH(K13)+VLOOKUP($F13,'Membership Level'!$A$3:$B$15,2,FALSE),DAY(K13))) | M13: 3 | N13: =IF($L13="","",DATE(YEAR($L13),MONTH($L13),DAY($L13)-$M13)) | O13: =IF($L13="","",IF(DAYS360(NOW(),$L13)>=0,DAYS360(NOW(),$L13),"")) | P13: =IF(OR(H13="",H13=0,F13="",K13=""),"",I13/H13*VLOOKUP(F13,'Membership Level'!$A$3:$C$15,3,FALSE)+K13)
A14: CAP/SW/403 | B14: 46127 | C14: SINGH | D14: MAYANK | E14: 8294267125 | F14: ='Membership Level'!A12 | G14: MONTHLY (KID) | H14: 3500 | I14: 3500 | J14: =IF(H14="","",H14-I14) | K14: 46127 | L14: =IF(OR(K14="",$F14=""),"",DATE(YEAR(K14),MONTH(K14)+VLOOKUP($F14,'Membership Level'!$A$3:$B$15,2,FALSE),DAY(K14))) | M14: 3 | N14: =IF($L14="","",DATE(YEAR($L14),MONTH($L14),DAY($L14)-$M14)) | O14: =IF($L14="","",IF(DAYS360(NOW(),$L14)>=0,DAYS360(NOW(),$L14),"")) | P14: =IF(OR(H14="",H14=0,F14="",K14=""),"",I14/H14*VLOOKUP(F14,'Membership Level'!$A$3:$C$15,3,FALSE)+K14)
A15: CAP/SW/404 | B15: 46127 | C15: SINGH | D15: ARK | E15: 8294267125 | F15: ='Membership Level'!A12 | G15: MONTHLY | H15: 4000 | I15: 4000 | J15: =IF(H15="","",H15-I15) | K15: 46127 | L15: =IF(OR(K15="",$F15=""),"",DATE(YEAR(K15),MONTH(K15)+VLOOKUP($F15,'Membership Level'!$A$3:$B$15,2,FALSE),DAY(K15))) | M15: 3 | N15: =IF($L15="","",DATE(YEAR($L15),MONTH($L15),DAY($L15)-$M15)) | O15: =IF($L15="","",IF(DAYS360(NOW(),$L15)>=0,DAYS360(NOW(),$L15),"")) | P15: =IF(OR(H15="",H15=0,F15="",K15=""),"",I15/H15*VLOOKUP(F15,'Membership Level'!$A$3:$C$15,3,FALSE)+K15)
A16: CAP/SW/405 | B16: 46127 | C16: JAMSHED | D16: YUMNA | E16: 8340630594 | F16: ='Membership Level'!A16 | G16: 3MONTHS (3DAYS, KID) | H16: 7000 | I16: 7000 | J16: =IF(H16="","",H16-I16) | K16: 46127 | L16: =IF(OR(K16="",$F16=""),"",DATE(YEAR(K16),MONTH(K16)+VLOOKUP($F16,'Membership Level'!$A$3:$B$15,2,FALSE),DAY(K16))) | M16: 3 | N16: =IF($L16="","",DATE(YEAR($L16),MONTH($L16),DAY($L16)-$M16)) | O16: =IF($L16="","",IF(DAYS360(NOW(),$L16)>=0,DAYS360(NOW(),$L16),"")) | P16: =IF(OR(H16="",H16=0,F16="",K16=""),"",I16/H16*VLOOKUP(F16,'Membership Level'!$A$3:$C$15,3,FALSE)+K16) | Q16: RENEW UPTO 15/05/26
A17: CAP/SW/406 | B17: 46127 | C17: SINHA | D17: SURYA | E17: 9304834745 | F17: ='Membership Level'!A12 | G17: MONTHLY (KID) | H17: 3500 | I17: 3500 | J17: =IF(H17="","",H17-I17) | K17: 46127 | L17: =IF(OR(K17="",$F17=""),"",DATE(YEAR(K17),MONTH(K17)+VLOOKUP($F17,'Membership Level'!$A$3:$B$15,2,FALSE),DAY(K17))) | M17: 3 | N17: =IF($L17="","",DATE(YEAR($L17),MONTH($L17),DAY($L17)-$M17)) | O17: =IF($L17="","",IF(DAYS360(NOW(),$L17)>=0,DAYS360(NOW(),$L17),"")) | P17: =IF(OR(H17="",H17=0,F17="",K17=""),"",I17/H17*VLOOKUP(F17,'Membership Level'!$A$3:$C$15,3,FALSE)+K17)
A18: CAP/SW/407 | B18: 46127 | C18: PANDEY | D18: VIDUR | E18: 9296863309 | F18: ='Membership Level'!A12 | G18: MONTHLY | H18: 4400 | I18: 4400 | J18: =IF(H18="","",H18-I18) | K18: 46127 | L18: =IF(OR(K18="",$F18=""),"",DATE(YEAR(K18),MONTH(K18)+VLOOKUP($F18,'Membership Level'!$A$3:$B$15,2,FALSE),DAY(K18))) | M18: 3 | N18: =IF($L18="","",DATE(YEAR($L18),MONTH($L18),DAY($L18)-$M18)) | O18: =IF($L18="","",IF(DAYS360(NOW(),$L18)>=0,DAYS360(NOW(),$L18),"")) | P18: =IF(OR(H18="",H18=0,F18="",K18=""),"",I18/H18*VLOOKUP(F18,'Membership Level'!$A$3:$C$15,3,FALSE)+K18)
A19: CAP/SW/408 | B19: 46128 | C19: KHAN | D19: M.D ASLAM | E19: 7484030479 | F19: ='Membership Level'!A12 | G19: MONTHLY | H19: 4000 | I19: 4000 | J19: =IF(H19="","",H19-I19) | K19: 46128 | L19: =IF(OR(K19="",$F19=""),"",DATE(YEAR(K19),MONTH(K19)+VLOOKUP($F19,'Membership Level'!$A$3:$B$15,2,FALSE),DAY(K19))) | M19: 3 | N19: =IF($L19="","",DATE(YEAR($L19),MONTH($L19),DAY($L19)-$M19)) | O19: =IF($L19="","",IF(DAYS360(NOW(),$L19)>=0,DAYS360(NOW(),$L19),"")) | P19: =IF(OR(H19="",H19=0,F19="",K19=""),"",I19/H19*VLOOKUP(F19,'Membership Level'!$A$3:$C$15,3,FALSE)+K19)
A20: CAP/SW/409 | B20: 46128 | C20: KHAN | D20: SAKIB | E20: 9110164371 | F20: ='Membership Level'!A12 | G20: MONTHLY | H20: 4000 | I20: 4000 | J20: =IF(H20="","",H20-I20) | K20: 46128 | L20: =IF(OR(K20="",$F20=""),"",DATE(YEAR(K20),MONTH(K20)+VLOOKUP($F20,'Membership Level'!$A$3:$B$15,2,FALSE),DAY(K20))) | M20: 3 | N20: =IF($L20="","",DATE(YEAR($L20),MONTH($L20),DAY($L20)-$M20)) | O20: =IF($L20="","",IF(DAYS360(NOW(),$L20)>=0,DAYS360(NOW(),$L20),"")) | P20: =IF(OR(H20="",H20=0,F20="",K20=""),"",I20/H20*VLOOKUP(F20,'Membership Level'!$A$3:$C$15,3,FALSE)+K20)
A21: CAP/SW/410 | B21: 46128 | D21: ADIT | E21: 7992298315 | F21: ='Membership Level'!A12 | G21: MONTHLY | H21: 3500 | I21: 3500 | J21: =IF(H21="","",H21-I21) | K21: 46128 | L21: =IF(OR(K21="",$F21=""),"",DATE(YEAR(K21),MONTH(K21)+VLOOKUP($F21,'Membership Level'!$A$3:$B$15,2,FALSE),DAY(K21))) | M21: 3 | N21: =IF($L21="","",DATE(YEAR($L21),MONTH($L21),DAY($L21)-$M21)) | O21: =IF($L21="","",IF(DAYS360(NOW(),$L21)>=0,DAYS360(NOW(),$L21),"")) | P21: =IF(OR(H21="",H21=0,F21="",K21=""),"",I21/H21*VLOOKUP(F21,'Membership Level'!$A$3:$C$15,3,FALSE)+K21)
A22: CAP/SW/411 | B22: 46128 | C22: NEMATULLAH | D22: MOHAMMAD | E22: 9572274353 | F22: ='Membership Level'!A12 | G22: MONTHLY | H22: 4400 | I22: 4400 | J22: =IF(H22="","",H22-I22) | K22: 46128 | L22: =IF(OR(K22="",$F22=""),"",DATE(YEAR(K22),MONTH(K22)+VLOOKUP($F22,'Membership Level'!$A$3:$B$15,2,FALSE),DAY(K22))) | M22: 3 | N22: =IF($L22="","",DATE(YEAR($L22),MONTH($L22),DAY($L22)-$M22)) | O22: =IF($L22="","",IF(DAYS360(NOW(),$L22)>=0,DAYS360(NOW(),$L22),"")) | P22: =IF(OR(H22="",H22=0,F22="",K22=""),"",I22/H22*VLOOKUP(F22,'Membership Level'!$A$3:$C$15,3,FALSE)+K22)
A23: CAP/SW/412 | B23: 46128 | C23: SINGH | D23: MYRA | E23: 9905514665 | F23: ='Membership Level'!A12 | G23: MONTHLY (3 DAY KID ) | H23: 2800 | I23: 2800 | J23: =IF(H23="","",H23-I23) | K23: 46128 | L23: =IF(OR(K23="",$F23=""),"",DATE(YEAR(K23),MONTH(K23)+VLOOKUP($F23,'Membership Level'!$A$3:$B$15,2,FALSE),DAY(K23))) | M23: 3 | N23: =IF($L23="","",DATE(YEAR($L23),MONTH($L23),DAY($L23)-$M23)) | O23: =IF($L23="","",IF(DAYS360(NOW(),$L23)>=0,DAYS360(NOW(),$L23),"")) | P23: =IF(OR(H23="",H23=0,F23="",K23=""),"",I23/H23*VLOOKUP(F23,'Membership Level'!$A$3:$C$15,3,FALSE)+K23)
A24: CAP/SW/413 | B24: 46128 | C24: SINGH | D24: AAKANSHA | E24: 7091975237 | F24: ='Membership Level'!A12 | G24: MONTHLY (3 DAY) | H24: 3300 | I24: 3300 | J24: =IF(H24="","",H24-I24) | K24: 46128 | L24: =IF(OR(K24="",$F24=""),"",DATE(YEAR(K24),MONTH(K24)+VLOOKUP($F24,'Membership Level'!$A$3:$B$15,2,FALSE),DAY(K24))) | M24: 3 | N24: =IF($L24="","",DATE(YEAR($L24),MONTH($L24),DAY($L24)-$M24)) | O24: =IF($L24="","",IF(DAYS360(NOW(),$L24)>=0,DAYS360(NOW(),$L24),"")) | P24: =IF(OR(H24="",H24=0,F24="",K24=""),"",I24/H24*VLOOKUP(F24,'Membership Level'!$A$3:$C$15,3,FALSE)+K24)
A25: CAP/SW/414 | B25: 46128 | C25: SINGH | D25: RASHMI | E25: 9334548082 | F25: ='Membership Level'!A12 | G25: MONTHLY | H25: 4400 | I25: 4400 | J25: =IF(H25="","",H25-I25) | K25: 46128 | L25: =IF(OR(K25="",$F25=""),"",DATE(YEAR(K25),MONTH(K25)+VLOOKUP($F25,'Membership Level'!$A$3:$B$15,2,FALSE),DAY(K25))) | M25: 3 | N25: =IF($L25="","",DATE(YEAR($L25),MONTH($L25),DAY($L25)-$M25)) | O25: =IF($L25="","",IF(DAYS360(NOW(),$L25)>=0,DAYS360(NOW(),$L25),"")) | P25: =IF(OR(H25="",H25=0,F25="",K25=""),"",I25/H25*VLOOKUP(F25,'Membership Level'!$A$3:$C$15,3,FALSE)+K25)
A26: CAP/SW/415 | B26: 46129 | C26: KUMAR | D26: RAJENDRA | E26: 7004522943 | F26: ='Membership Level'!A12 | G26: MONTHLY | H26: 4000 | I26: 4000 | J26: =IF(H26="","",H26-I26) | K26: 46129 | L26: =IF(OR(K26="",$F26=""),"",DATE(YEAR(K26),MONTH(K26)+VLOOKUP($F26,'Membership Level'!$A$3:$B$15,2,FALSE),DAY(K26))) | M26: 3 | N26: =IF($L26="","",DATE(YEAR($L26),MONTH($L26),DAY($L26)-$M26)) | O26: =IF($L26="","",IF(DAYS360(NOW(),$L26)>=0,DAYS360(NOW(),$L26),"")) | P26: =IF(OR(H26="",H26=0,F26="",K26=""),"",I26/H26*VLOOKUP(F26,'Membership Level'!$A$3:$C$15,3,FALSE)+K26)
A27: CAP/SW/416 | B27: 46129 | C27: RAJ | D27: AYUSH VARDHAN | E27: 8789432896 | F27: ='Membership Level'!A12 | G27: MONTHLY | H27: 4400 | I27: 4400 | J27: =IF(H27="","",H27-I27) | K27: 46129 | L27: =IF(OR(K27="",$F27=""),"",DATE(YEAR(K27),MONTH(K27)+VLOOKUP($F27,'Membership Level'!$A$3:$B$15,2,FALSE),DAY(K27))) | M27: 3 | N27: =IF($L27="","",DATE(YEAR($L27),MONTH($L27),DAY($L27)-$M27)) | O27: =IF($L27="","",IF(DAYS360(NOW(),$L27)>=0,DAYS360(NOW(),$L27),"")) | P27: =IF(OR(H27="",H27=0,F27="",K27=""),"",I27/H27*VLOOKUP(F27,'Membership Level'!$A$3:$C$15,3,FALSE)+K27)
A28: CAP/SW/417 | B28: 46129 | C28: KUMARI | D28: ANSHIKA | E28: 8294608133 | F28: ='Membership Level'!A12 | G28: MONTHLY | H28: 3300 | I28: 3300 | J28: =IF(H28="","",H28-I28) | K28: 46129 | L28: =IF(OR(K28="",$F28=""),"",DATE(YEAR(K28),MONTH(K28)+VLOOKUP($F28,'Membership Level'!$A$3:$B$15,2,FALSE),DAY(K28))) | M28: 3 | N28: =IF($L28="","",DATE(YEAR($L28),MONTH($L28),DAY($L28)-$M28)) | O28: =IF($L28="","",IF(DAYS360(NOW(),$L28)>=0,DAYS360(NOW(),$L28),"")) | P28: =IF(OR(H28="",H28=0,F28="",K28=""),"",I28/H28*VLOOKUP(F28,'Membership Level'!$A$3:$C$15,3,FALSE)+K28)
A29: CAP/SW/418 | B29: 46129 | C29: KUMAR | D29: ANSH | E29: 8294608133 | F29: ='Membership Level'!A12 | G29: MONTHLY | H29: 3800 | I29: 3800 | J29: =IF(H29="","",H29-I29) | K29: 46129 | L29: =IF(OR(K29="",$F29=""),"",DATE(YEAR(K29),MONTH(K29)+VLOOKUP($F29,'Membership Level'!$A$3:$B$15,2,FALSE),DAY(K29))) | M29: 3 | N29: =IF($L29="","",DATE(YEAR($L29),MONTH($L29),DAY($L29)-$M29)) | O29: =IF($L29="","",IF(DAYS360(NOW(),$L29)>=0,DAYS360(NOW(),$L29),"")) | P29: =IF(OR(H29="",H29=0,F29="",K29=""),"",I29/H29*VLOOKUP(F29,'Membership Level'!$A$3:$C$15,3,FALSE)+K29)
A30: CAP/SW/419 | B30: 46129 | C30: SARAJ | D30: ANAAYA | E30: 8554925434 | F30: ='Membership Level'!A12 | G30: MONTHLY | H30: 3800 | I30: 3800 | J30: =IF(H30="","",H30-I30) | K30: 46129 | L30: =IF(OR(K30="",$F30=""),"",DATE(YEAR(K30),MONTH(K30)+VLOOKUP($F30,'Membership Level'!$A$3:$B$15,2,FALSE),DAY(K30))) | M30: 3 | N30: =IF($L30="","",DATE(YEAR($L30),MONTH($L30),DAY($L30)-$M30)) | O30: =IF($L30="","",IF(DAYS360(NOW(),$L30)>=0,DAYS360(NOW(),$L30),"")) | P30: =IF(OR(H30="",H30=0,F30="",K30=""),"",I30/H30*VLOOKUP(F30,'Membership Level'!$A$3:$C$15,3,FALSE)+K30)
A31: CAP/SW/420 | B31: 46129 | C31: SRIVASTAVA | D31: SARTHIKA | E31: 6387464675 | F31: ='Membership Level'!A12 | G31: MONTHLY (3 DAY KID ) | H31: 2800 | I31: 2800 | J31: =IF(H31="","",H31-I31) | K31: 46129 | L31: =IF(OR(K31="",$F31=""),"",DATE(YEAR(K31),MONTH(K31)+VLOOKUP($F31,'Membership Level'!$A$3:$B$15,2,FALSE),DAY(K31))) | M31: 3 | N31: =IF($L31="","",DATE(YEAR($L31),MONTH($L31),DAY($L31)-$M31)) | O31: =IF($L31="","",IF(DAYS360(NOW(),$L31)>=0,DAYS360(NOW(),$L31),"")) | P31: =IF(OR(H31="",H31=0,F31="",K31=""),"",I31/H31*VLOOKUP(F31,'Membership Level'!$A$3:$C$15,3,FALSE)+K31)
A32: CAP/SW/421 | B32: 46130 | C32: RANJAN | D32: RASHMI | E32: 8434007319 | F32: ='Membership Level'!A12 | G32: MONTHLY | H32: 4400 | I32: 3000 | J32: =IF(H32="","",H32-I32) | K32: 46130 | L32: =IF(OR(K32="",$F32=""),"",DATE(YEAR(K32),MONTH(K32)+VLOOKUP($F32,'Membership Level'!$A$3:$B$15,2,FALSE),DAY(K32))) | M32: 3 | N32: =IF($L32="","",DATE(YEAR($L32),MONTH($L32),DAY($L32)-$M32)) | O32: =IF($L32="","",IF(DAYS360(NOW(),$L32)>=0,DAYS360(NOW(),$L32),"")) | P32: =IF(OR(H32="",H32=0,F32="",K32=""),"",I32/H32*VLOOKUP(F32,'Membership Level'!$A$3:$C$15,3,FALSE)+K32)
A33: CAP/SW/422 | B33: 46130 | C33: CHANDRA | D33: SHRESH | E33: 8002081222 | F33: ='Membership Level'!A12 | G33: MONTHLY (3 DAY ) | H33: 3300 | I33: 3300 | J33: =IF(H33="","",H33-I33) | K33: 46130 | L33: =IF(OR(K33="",$F33=""),"",DATE(YEAR(K33),MONTH(K33)+VLOOKUP($F33,'Membership Level'!$A$3:$B$15,2,FALSE),DAY(K33))) | M33: 3 | N33: =IF($L33="","",DATE(YEAR($L33),MONTH($L33),DAY($L33)-$M33)) | O33: =IF($L33="","",IF(DAYS360(NOW(),$L33)>=0,DAYS360(NOW(),$L33),"")) | P33: =IF(OR(H33="",H33=0,F33="",K33=""),"",I33/H33*VLOOKUP(F33,'Membership Level'!$A$3:$C$15,3,FALSE)+K33)
A34: CAP/SW/423 | B34: 46130 | C34: SINGH | D34: NAVYA | E34: 9708216967 | F34: ='Membership Level'!A12 | G34: MONTHLY (2 DAY KID ) | H34: 2200 | I34: 2200 | J34: =IF(H34="","",H34-I34) | K34: 46130 | L34: =IF(OR(K34="",$F34=""),"",DATE(YEAR(K34),MONTH(K34)+VLOOKUP($F34,'Membership Level'!$A$3:$B$15,2,FALSE),DAY(K34))) | M34: 3 | N34: =IF($L34="","",DATE(YEAR($L34),MONTH($L34),DAY($L34)-$M34)) | O34: =IF($L34="","",IF(DAYS360(NOW(),$L34)>=0,DAYS360(NOW(),$L34),"")) | P34: =IF(OR(H34="",H34=0,F34="",K34=""),"",I34/H34*VLOOKUP(F34,'Membership Level'!$A$3:$C$15,3,FALSE)+K34)
A35: CAP/SW/424 | B35: 46130 | D35: AGASTYA | E35: 9708216967 | F35: ='Membership Level'!A12 | G35: MONTHLY (2 DAY KID ) | H35: 2200 | I35: 2200 | J35: =IF(H35="","",H35-I35) | K35: 46130 | L35: =IF(OR(K35="",$F35=""),"",DATE(YEAR(K35),MONTH(K35)+VLOOKUP($F35,'Membership Level'!$A$3:$B$15,2,FALSE),DAY(K35))) | M35: 3 | N35: =IF($L35="","",DATE(YEAR($L35),MONTH($L35),DAY($L35)-$M35)) | O35: =IF($L35="","",IF(DAYS360(NOW(),$L35)>=0,DAYS360(NOW(),$L35),"")) | P35: =IF(OR(H35="",H35=0,F35="",K35=""),"",I35/H35*VLOOKUP(F35,'Membership Level'!$A$3:$C$15,3,FALSE)+K35)
A36: CAP/SW/425 | B36: 46130 | C36: SHREE | D36: PUSHKAR | E36: 8789230720 | F36: ='Membership Level'!A12 | G36: MONTHLY | H36: 4000 | I36: 4000 | J36: =IF(H36="","",H36-I36) | K36: 46130 | L36: =IF(OR(K36="",$F36=""),"",DATE(YEAR(K36),MONTH(K36)+VLOOKUP($F36,'Membership Level'!$A$3:$B$15,2,FALSE),DAY(K36))) | M36: 3 | N36: =IF($L36="","",DATE(YEAR($L36),MONTH($L36),DAY($L36)-$M36)) | O36: =IF($L36="","",IF(DAYS360(NOW(),$L36)>=0,DAYS360(NOW(),$L36),"")) | P36: =IF(OR(H36="",H36=0,F36="",K36=""),"",I36/H36*VLOOKUP(F36,'Membership Level'!$A$3:$C$15,3,FALSE)+K36)
A37: CAP/SW/426 | B37: 46130 | C37: SHREE | D37: PARTH | E37: 8789230720 | F37: ='Membership Level'!A12 | G37: MONTHLY (KID ) | H37: 3800 | I37: 3800 | J37: =IF(H37="","",H37-I37) | K37: 46130 | L37: =IF(OR(K37="",$F37=""),"",DATE(YEAR(K37),MONTH(K37)+VLOOKUP($F37,'Membership Level'!$A$3:$B$15,2,FALSE),DAY(K37))) | M37: 3 | N37: =IF($L37="","",DATE(YEAR($L37),MONTH($L37),DAY($L37)-$M37)) | O37: =IF($L37="","",IF(DAYS360(NOW(),$L37)>=0,DAYS360(NOW(),$L37),"")) | P37: =IF(OR(H37="",H37=0,F37="",K37=""),"",I37/H37*VLOOKUP(F37,'Membership Level'!$A$3:$C$15,3,FALSE)+K37)
A38: CAP/SW/427 | B38: 46130 | D38: AIZA | E38: 9934061619 | F38: ='Membership Level'!A12 | G38: MONTHLY (2 DAY ) | H38: 2500 | I38: 2500 | J38: =IF(H38="","",H38-I38) | K38: 46130 | L38: =IF(OR(K38="",$F38=""),"",DATE(YEAR(K38),MONTH(K38)+VLOOKUP($F38,'Membership Level'!$A$3:$B$15,2,FALSE),DAY(K38))) | M38: 3 | N38: =IF($L38="","",DATE(YEAR($L38),MONTH($L38),DAY($L38)-$M38)) | O38: =IF($L38="","",IF(DAYS360(NOW(),$L38)>=0,DAYS360(NOW(),$L38),"")) | P38: =IF(OR(H38="",H38=0,F38="",K38=""),"",I38/H38*VLOOKUP(F38,'Membership Level'!$A$3:$C$15,3,FALSE)+K38)
A39: CAP/SW/428 | B39: 46130 | D39: ARISHA | E39: 9934061619 | F39: ='Membership Level'!A12 | G39: MONTHLY (2 DAY KID ) | H39: 2500 | I39: 2500 | J39: =IF(H39="","",H39-I39) | K39: 46130 | L39: =IF(OR(K39="",$F39=""),"",DATE(YEAR(K39),MONTH(K39)+VLOOKUP($F39,'Membership Level'!$A$3:$B$15,2,FALSE),DAY(K39))) | M39: 3 | N39: =IF($L39="","",DATE(YEAR($L39),MONTH($L39),DAY($L39)-$M39)) | O39: =IF($L39="","",IF(DAYS360(NOW(),$L39)>=0,DAYS360(NOW(),$L39),"")) | P39: =IF(OR(H39="",H39=0,F39="",K39=""),"",I39/H39*VLOOKUP(F39,'Membership Level'!$A$3:$C$15,3,FALSE)+K39)
A40: CAP/SW/429 | B40: 46130 | C40: KUMAR | D40: MANISH | E40: 9168145450 | F40: ='Membership Level'!A12 | G40: MONTHLY (3 DAY ) | H40: 3300 | I40: 3300 | J40: =IF(H40="","",H40-I40) | K40: 46130 | L40: =IF(OR(K40="",$F40=""),"",DATE(YEAR(K40),MONTH(K40)+VLOOKUP($F40,'Membership Level'!$A$3:$B$15,2,FALSE),DAY(K40))) | M40: 3 | N40: =IF($L40="","",DATE(YEAR($L40),MONTH($L40),DAY($L40)-$M40)) | O40: =IF($L40="","",IF(DAYS360(NOW(),$L40)>=0,DAYS360(NOW(),$L40),"")) | P40: =IF(OR(H40="",H40=0,F40="",K40=""),"",I40/H40*VLOOKUP(F40,'Membership Level'!$A$3:$C$15,3,FALSE)+K40)
A41: CAP/SW/430 | B41: 46130 | C41: SINGH | D41: SHARVANI | E41: 9990621282 | F41: ='Membership Level'!A12 | G41: MONTHLY (KID ) | H41: 3800 | I41: 3800 | J41: =IF(H41="","",H41-I41) | K41: 46130 | L41: =IF(OR(K41="",$F41=""),"",DATE(YEAR(K41),MONTH(K41)+VLOOKUP($F41,'Membership Level'!$A$3:$B$15,2,FALSE),DAY(K41))) | M41: 3 | N41: =IF($L41="","",DATE(YEAR($L41),MONTH($L41),DAY($L41)-$M41)) | O41: =IF($L41="","",IF(DAYS360(NOW(),$L41)>=0,DAYS360(NOW(),$L41),"")) | P41: =IF(OR(H41="",H41=0,F41="",K41=""),"",I41/H41*VLOOKUP(F41,'Membership Level'!$A$3:$C$15,3,FALSE)+K41)
A42: CAP/SW/431 | B42: 46130 | C42: BHATTACHARYA | D42: DIPANWITA | E42: 9771689875 | F42: ='Membership Level'!A14 | G42: 6 MONTHS (3 DAY ) | H42: 14500 | I42: 8000 | J42: =IF(H42="","",H42-I42) | K42: 46130 | L42: =IF(OR(K42="",$F42=""),"",DATE(YEAR(K42),MONTH(K42)+VLOOKUP($F42,'Membership Level'!$A$3:$B$15,2,FALSE),DAY(K42))) | M42: 3 | N42: =IF($L42="","",DATE(YEAR($L42),MONTH($L42),DAY($L42)-$M42)) | O42: =IF($L42="","",IF(DAYS360(NOW(),$L42)>=0,DAYS360(NOW(),$L42),"")) | P42: =IF(OR(H42="",H42=0,F42="",K42=""),"",I42/H42*VLOOKUP(F42,'Membership Level'!$A$3:$C$15,3,FALSE)+K42)
A43: CAP/SW/432 | B43: 46130 | C43: VERMA | D43: AKASH KUMAR | E43: 9591135769 | F43: ='Membership Level'!A12 | G43: MONTHLY | H43: 4000 | I43: 4000 | J43: =IF(H43="","",H43-I43) | K43: 46130 | L43: =IF(OR(K43="",$F43=""),"",DATE(YEAR(K43),MONTH(K43)+VLOOKUP($F43,'Membership Level'!$A$3:$B$15,2,FALSE),DAY(K43))) | M43: 3 | N43: =IF($L43="","",DATE(YEAR($L43),MONTH($L43),DAY($L43)-$M43)) | O43: =IF($L43="","",IF(DAYS360(NOW(),$L43)>=0,DAYS360(NOW(),$L43),"")) | P43: =IF(OR(H43="",H43=0,F43="",K43=""),"",I43/H43*VLOOKUP(F43,'Membership Level'!$A$3:$C$15,3,FALSE)+K43)
A44: CAP/SW/433 | B44: 46130 | C44: ANAND | D44: ANKITESH | E44: 7979828225 | F44: ='Membership Level'!A12 | G44: MONTHLY | H44: 4000 | I44: 4000 | J44: =IF(H44="","",H44-I44) | K44: 46130 | L44: =IF(OR(K44="",$F44=""),"",DATE(YEAR(K44),MONTH(K44)+VLOOKUP($F44,'Membership Level'!$A$3:$B$15,2,FALSE),DAY(K44))) | M44: 3 | N44: =IF($L44="","",DATE(YEAR($L44),MONTH($L44),DAY($L44)-$M44)) | O44: =IF($L44="","",IF(DAYS360(NOW(),$L44)>=0,DAYS360(NOW(),$L44),"")) | P44: =IF(OR(H44="",H44=0,F44="",K44=""),"",I44/H44*VLOOKUP(F44,'Membership Level'!$A$3:$C$15,3,FALSE)+K44)
...
